Workbook

Sheet Portada
B5: Sistema de Bibliotecas - Apoyo a la Investigación
B10: Informe de Productividad Científica
B15: 2024 – 2025
B21: Investigadores con afiliación · Universidad Finis Terrae
B23: Información recopilada a partir de SciVal y Scopus
C29: 589 | F29: 396 | I29: 853
C31: Publicaciones únicas | F31: Investigadores | I31: Participaciones (autoría/coautoría)
B45: UNIVERSIDAD FINIS TERRAE
B49: Santiago de Chile · 2026

Sheet Investigadores
A1: Ranking de investigadores · Universidad Finis Terrae · 2024–2025 | AA1: Autor (norm.) | AB1: Año | AC1: Tipo
A2: Publicaciones con afiliación institucional (participaciones autor–publicación). Fuente: SciVal y Scopus. | AA2: Mujika I. | AB2: 2024 | AC2: Article
AA3: Fernández-Verdejo R. | AB3: 2024 | AC3: Review
A4: # | B4: Investigador | C4: 2024 | D4: 2025 | E4: Total | AA4: Tuñón-Suárez M. | AB4: 2024 | AC4: Review
A5: 1 | B5: Orellana-Donoso M. | C5: =COUNTIFS($AA:$AA,$B5,$AB:$AB,2024) -> 16 | D5: =COUNTIFS($AA:$AA,$B5,$AB:$AB,2025) -> 16 | E5: =C5+D5 -> 32 | AA5: Chavez-Reyes A. | AB5: 2024 | AC5: Review
A6: 2 | B6: Yanine F.F. | C6: =COUNTIFS($AA:$AA,$B6,$AB:$AB,2024) -> 13 | D6: =COUNTIFS($AA:$AA,$B6,$AB:$AB,2025) -> 9 | E6: =C6+D6 -> 22 | AA6: Mayo B. | AB6: 2024 | AC6: Review
A7: 3 | B7: Ferre A. | C7: =COUNTIFS($AA:$AA,$B7,$AB:$AB,2024) -> 9 | D7: =COUNTIFS($AA:$AA,$B7,$AB:$AB,2025) -> 12 | E7: =C7+D7 -> 21 | AA7: Penroz S. | AB7: 2024 | AC7: Review
A8: 4 | B8: Mujika I. | C8: =COUNTIFS($AA:$AA,$B8,$AB:$AB,2024) -> 7 | D8: =COUNTIFS($AA:$AA,$B8,$AB:$AB,2025) -> 14 | E8: =C8+D8 -> 21 | AA8: Torres K. | AB8: 2024 | AC8: Review
A9: 5 | B9: Giglio A. | C9: =COUNTIFS($AA:$AA,$B9,$AB:$AB,2024) -> 6 | D9: =COUNTIFS($AA:$AA,$B9,$AB:$AB,2025) -> 13 | E9: =C9+D9 -> 19 | AA9: Simón L. | AB9: 2024 | AC9: Review
A10: 6 | B10: Strauss F.J. | C10: =COUNTIFS($AA:$AA,$B10,$AB:$AB,2024) -> 10 | D10: =COUNTIFS($AA:$AA,$B10,$AB:$AB,2025) -> 6 | E10: =C10+D10 -> 16 | AA10: Fuentealba J.M. | AB10: 2025 | AC10: Review
A11: 7 | B11: Díaz F. | C11: =COUNTIFS($AA:$AA,$B11,$AB:$AB,2024) -> 5 | D11: =COUNTIFS($AA:$AA,$B11,$AB:$AB,2025) -> 10 | E11: =C11+D11 -> 15 | AA11: Hidalgo-Rosa Y. | AB11: 2024 | AC11: Article
A12: 8 | B12: Henríquez-Olguín C. | C12: =COUNTIFS($AA:$AA,$B12,$AB:$AB,2024) -> 6 | D12: =COUNTIFS($AA:$AA,$B12,$AB:$AB,2025) -> 7 | E12: =C12+D12 -> 13 | AA12: Strauss F.J. | AB12: 2024 | AC12: Article
A13: 9 | B13: López-Arana S. | C13: =COUNTIFS($AA:$AA,$B13,$AB:$AB,2024) -> 3 | D13: =COUNTIFS($AA:$AA,$B13,$AB:$AB,2025) -> 10 | E13: =C13+D13 -> 13 | AA13: Yanine F.F. | AB13: 2025 | AC13: Review
A14: 10 | B14: Fernández-Verdejo R. | C14: =COUNTIFS($AA:$AA,$B14,$AB:$AB,2024) -> 9 | D14: =COUNTIFS($AA:$AA,$B14,$AB:$AB,2025) -> 3 | E14: =C14+D14 -> 12 | AA14: Yanine F.F. | AB14: 2024 | AC14: Article
A15: 11 | B15: Mariotti-Celis M.S. | C15: =COUNTIFS($AA:$AA,$B15,$AB:$AB,2024) -> 8 | D15: =COUNTIFS($AA:$AA,$B15,$AB:$AB,2025) -> 4 | E15: =C15+D15 -> 12 | AA15: Fernández-Verdejo R. | AB15: 2024 | AC15: Review
A16: 12 | B16: Cancino-López J. | C16: =COUNTIFS($AA:$AA,$B16,$AB:$AB,2024) -> 4 | D16: =COUNTIFS($AA:$AA,$B16,$AB:$AB,2025) -> 7 | E16: =C16+D16 -> 11 | AA16: Henríquez-Olguín C. | AB16: 2024 | AC16: Article
... A400: 396 | B400: Candell M.B. | C400: =COUNTIFS($AA:$AA,$B400,$AB:$AB,2024) -> 0 | D400: =COUNTIFS($AA:$AA,$B400,$AB:$AB,2025) -> 1 | E400: =C400+D400 -> 1 | AA400: Giglio A. | AB400: 2025 | AC400: Letter
AA401: Ferre A. | AB401: 2025 | AC401: Letter
AA402: Garcia J. | AB402: 2025 | AC402: Letter
AA403: González I. | AB403: 2025 | AC403: Article
AA404: Maldonado-Agurto R. | AB404: 2025 | AC404: Article
AA405: Benites M.H. | AB405: 2025 | AC405: Article
AA406: Saenz A. | AB406: 2025 | AC406: Article
AA407: Dreyse J. | AB407: 2025 | AC407: Article
AA408: Giglio A. | AB408: 2025 | AC408: Article
AA409: Díaz F. | AB409: 2025 | AC409: Article
AA410: Carvajal C. | AB410: 2025 | AC410: Article
AA411: Orellana-Donoso M. | AB411: 2024 | AC411: Review
AA412: Orellana-Donoso M. | AB412: 2024 | AC412: Review
... AA854: Zambrano C. | AB854: 2025 | AC854: Conference Paper

Sheet Resumen y gráficos
A1: Resumen y gráficos · Universidad Finis Terrae · 2024–2025 | AA1: Autor (norm.) | AB1: Año | AC1: Tipo
A2: Fuente: Scopus con afiliación UFT (2024–2025). Ranking y matriz por investigador = participaciones autor-publicación (cada par autor-paper único). Tabla y gráfico 'por tipo' = publicaciones únicas (589, sin duplicar coautorías). Autores agrupados por apellido + inicial. | AA2: Mujika I. | AB2: 2024 | AC2: Article
AA3: Fernández-Verdejo R. | AB3: 2024 | AC3: Review
A4: # | B4: Investigador | C4: 2024 | D4: 2025 | E4: Total | G4: Tipo de publicación | H4: Publ. únicas | AA4: Tuñón-Suárez M. | AB4: 2024 | AC4: Review
A5: 1 | B5: Orellana-Donoso M. | C5: =COUNTIFS($AA:$AA,$B5,$AB:$AB,2024) -> 16 | D5: =COUNTIFS($AA:$AA,$B5,$AB:$AB,2025) -> 16 | E5: =C5+D5 -> 32 | G5: Article | H5: =COUNTIF('Publicaciones unificadas'!$D$2:$D$590,G5) -> 412 | AA5: Chavez-Reyes A. | AB5: 2024 | AC5: Review
A6: 2 | B6: Yanine F.F. | C6: =COUNTIFS($AA:$AA,$B6,$AB:$AB,2024) -> 13 | D6: =COUNTIFS($AA:$AA,$B6,$AB:$AB,2025) -> 9 | E6: =C6+D6 -> 22 | G6: Review | H6: =COUNTIF('Publicaciones unificadas'!$D$2:$D$590,G6) -> 103 | AA6: Mayo B. | AB6: 2024 | AC6: Review
A7: 3 | B7: Ferre A. | C7: =COUNTIFS($AA:$AA,$B7,$AB:$AB,2024) -> 9 | D7: =COUNTIFS($AA:$AA,$B7,$AB:$AB,2025) -> 12 | E7: =C7+D7 -> 21 | G7: Letter | H7: =COUNTIF('Publicaciones unificadas'!$D$2:$D$590,G7) -> 21 | AA7: Penroz S. | AB7: 2024 | AC7: Review
A8: 4 | B8: Mujika I. | C8: =COUNTIFS($AA:$AA,$B8,$AB:$AB,2024) -> 7 | D8: =COUNTIFS($AA:$AA,$B8,$AB:$AB,2025) -> 14 | E8: =C8+D8 -> 21 | G8: Chapter | H8: =COUNTIF('Publicaciones unificadas'!$D$2:$D$590,G8) -> 17 | AA8: Torres K. | AB8: 2024 | AC8: Review
A9: 5 | B9: Giglio A. | C9: =COUNTIFS($AA:$AA,$B9,$AB:$AB,2024) -> 6 | D9: =COUNTIFS($AA:$AA,$B9,$AB:$AB,2025) -> 13 | E9: =C9+D9 -> 19 | G9: Conference Paper | H9: =COUNTIF('Publicaciones unificadas'!$D$2:$D$590,G9) -> 14 | AA9: Simón L. | AB9: 2024 | AC9: Review
A10: 6 | B10: Strauss F.J. | C10: =COUNTIFS($AA:$AA,$B10,$AB:$AB,2024) -> 10 | D10: =COUNTIFS($AA:$AA,$B10,$AB:$AB,2025) -> 6 | E10: =C10+D10 -> 16 | G10: Editorial | H10: =COUNTIF('Publicaciones unificadas'!$D$2:$D$590,G10) -> 7 | AA10: Fuentealba J.M. | AB10: 2025 | AC10: Review
A11: 7 | B11: Díaz F. | C11: =COUNTIFS($AA:$AA,$B11,$AB:$AB,2024) -> 5 | D11: =COUNTIFS($AA:$AA,$B11,$AB:$AB,2025) -> 10 | E11: =C11+D11 -> 15 | G11: Erratum | H11: =COUNTIF('Publicaciones unificadas'!$D$2:$D$590,G11) -> 4 | AA11: Hidalgo-Rosa Y. | AB11: 2024 | AC11: Article
A12: 8 | B12: Henríquez-Olguín C. | C12: =COUNTIFS($AA:$AA,$B12,$AB:$AB,2024) -> 6 | D12: =COUNTIFS($AA:$AA,$B12,$AB:$AB,2025) -> 7 | E12: =C12+D12 -> 13 | G12: Note | H12: =COUNTIF('Publicaciones unificadas'!$D$2:$D$590,G12) -> 6 | AA12: Strauss F.J. | AB12: 2024 | AC12: Article
A13: 9 | B13: López-Arana S. | C13: =COUNTIFS($AA:$AA,$B13,$AB:$AB,2024) -> 3 | D13: =COUNTIFS($AA:$AA,$B13,$AB:$AB,2025) -> 10 | E13: =C13+D13 -> 13 | G13: Short Survey | H13: =COUNTIF('Publicaciones unificadas'!$D$2:$D$590,G13) -> 3 | AA13: Yanine F.F. | AB13: 2025 | AC13: Review
A14: 10 | B14: Fernández-Verdejo R. | C14: =COUNTIFS($AA:$AA,$B14,$AB:$AB,2024) -> 9 | D14: =COUNTIFS($AA:$AA,$B14,$AB:$AB,2025) -> 3 | E14: =C14+D14 -> 12 | G14: Book | H14: =COUNTIF('Publicaciones unificadas'!$D$2:$D$590,G14) -> 1 | AA14: Yanine F.F. | AB14: 2024 | AC14: Article
A15: 11 | B15: Mariotti-Celis M.S. | C15: =COUNTIFS($AA:$AA,$B15,$AB:$AB,2024) -> 8 | D15: =COUNTIFS($AA:$AA,$B15,$AB:$AB,2025) -> 4 | E15: =C15+D15 -> 12 | G15: Total | H15: =SUM(H5:H14) -> 588 | AA15: Fernández-Verdejo R. | AB15: 2024 | AC15: Review
A16: 12 | B16: Cancino-López J. | C16: =COUNTIFS($AA:$AA,$B16,$AB:$AB,2024) -> 4 | D16: =COUNTIFS($AA:$AA,$B16,$AB:$AB,2025) -> 7 | E16: =C16+D16 -> 11 | AA16: Henríquez-Olguín C. | AB16: 2024 | AC16: Article
A17: 13 | B17: Dreyse J. | C17: =COUNTIFS($AA:$AA,$B17,$AB:$AB,2024) -> 6 | D17: =COUNTIFS($AA:$AA,$B17,$AB:$AB,2025) -> 4 | E17: =C17+D17 -> 10 | G17: Investigador | H17: Article | I17: Review | J17: Letter | K17: Chapter | L17: Conf. Paper | M17: Otros | N17: Total | AA17: Salas-Guzmán N. | AB17: 2024 | AC17: Review
A18: 14 | B18: Bustos-Arriagada E. | C18: =COUNTIFS($AA:$AA,$B18,$AB:$AB,2024) -> 4 | D18: =COUNTIFS($AA:$AA,$B18,$AB:$AB,2025) -> 5 | E18: =C18+D18 -> 9 | G18: =B5 -> Orellana-Donoso M. | H18: =COUNTIFS($AA:$AA,$G18,$AC:$AC,"Article") -> 8 | I18: =COUNTIFS($AA:$AA,$G18,$AC:$AC,"Review") -> 23 | J18: =COUNTIFS($AA:$AA,$G18,$AC:$AC,"Letter") -> 0 | K18: =COUNTIFS($AA:$AA,$G18,$AC:$AC,"Chapter") -> 0 | L18: =COUNTIFS($AA:$AA,$G18,$AC:$AC,"Conference Paper") -> 0 | M18: =N18-SUM(H18:L18) -> 1 | N18: =E5 -> 32 | AA18: Yanine F.F. | AB18: 2024 | AC18: Article
A19: 15 | B19: Hidalgo M. | C19: =COUNTIFS($AA:$AA,$B19,$AB:$AB,2024) -> 2 | D19: =COUNTIFS($AA:$AA,$B19,$AB:$AB,2025) -> 7 | E19: =C19+D19 -> 9 | G19: =B6 -> Yanine F.F. | H19: =COUNTIFS($AA:$AA,$G19,$AC:$AC,"Article") -> 10 | I19: =COUNTIFS($AA:$AA,$G19,$AC:$AC,"Review") -> 2 | J19: =COUNTIFS($AA:$AA,$G19,$AC:$AC,"Letter") -> 0 | K19: =COUNTIFS($AA:$AA,$G19,$AC:$AC,"Chapter") -> 8 | L19: =COUNTIFS($AA:$AA,$G19,$AC:$AC,"Conference Paper") -> 2 | M19: =N19-SUM(H19:L19) -> 0 | N19: =E6 -> 22 | AA19: Morales J.-P. | AB19: 2024 | AC19: Short Survey
G20: =B7 -> Ferre A. | H20: =COUNTIFS($AA:$AA,$G20,$AC:$AC,"Article") -> 12 | I20: =COUNTIFS($AA:$AA,$G20,$AC:$AC,"Review") -> 4 | J20: =COUNTIFS($AA:$AA,$G20,$AC:$AC,"Letter") -> 5 | K20: =COUNTIFS($AA:$AA,$G20,$AC:$AC,"Chapter") -> 0 | L20: =COUNTIFS($AA:$AA,$G20,$AC:$AC,"Conference Paper") -> 0 | M20: =N20-SUM(H20:L20) -> 0 | N20: =E7 -> 21 | AA20: De la Fuente M. | AB20: 2025 | AC20: Article
G21: =B8 -> Mujika I. | H21: =COUNTIFS($AA:$AA,$G21,$AC:$AC,"Article") -> 16 | I21: =COUNTIFS($AA:$AA,$G21,$AC:$AC,"Review") -> 1 | J21: =COUNTIFS($AA:$AA,$G21,$AC:$AC,"Letter") -> 0 | K21: =COUNTIFS($AA:$AA,$G21,$AC:$AC,"Chapter") -> 1 | L21: =COUNTIFS($AA:$AA,$G21,$AC:$AC,"Conference Paper") -> 0 | M21: =N21-SUM(H21:L21) -> 3 | N21: =E8 -> 21 | AA21: Benites M.H. | AB21: 2025 | AC21: Review
G22: =B9 -> Giglio A. | H22: =COUNTIFS($AA:$AA,$G22,$AC:$AC,"Article") -> 12 | I22: =COUNTIFS($AA:$AA,$G22,$AC:$AC,"Review") -> 3 | J22: =COUNTIFS($AA:$AA,$G22,$AC:$AC,"Letter") -> 4 | K22: =COUNTIFS($AA:$AA,$G22,$AC:$AC,"Chapter") -> 0 | L22: =COUNTIFS($AA:$AA,$G22,$AC:$AC,"Conference Paper") -> 0 | M22: =N22-SUM(H22:L22) -> 0 | N22: =E9 -> 19 | AA22: Mujika I. | AB22: 2024 | AC22: Article
G23: =B10 -> Strauss F.J. | H23: =COUNTIFS($AA:$AA,$G23,$AC:$AC,"Article") -> 14 | I23: =COUNTIFS($AA:$AA,$G23,$AC:$AC,"Review") -> 2 | J23: =COUNTIFS($AA:$AA,$G23,$AC:$AC,"Letter") -> 0 | K23: =COUNTIFS($AA:$AA,$G23,$AC:$AC,"Chapter") -> 0 | L23: =COUNTIFS($AA:$AA,$G23,$AC:$AC,"Conference Paper") -> 0 | M23: =N23-SUM(H23:L23) -> 0 | N23: =E10 -> 16 | AA23: Ayares G. | AB23: 2025 | AC23: Review
G24: =B11 -> Díaz F. | H24: =COUNTIFS($AA:$AA,$G24,$AC:$AC,"Article") -> 8 | I24: =COUNTIFS($AA:$AA,$G24,$AC:$AC,"Review") -> 0 | J24: =COUNTIFS($AA:$AA,$G24,$AC:$AC,"Letter") -> 5 | K24: =COUNTIFS($AA:$AA,$G24,$AC:$AC,"Chapter") -> 0 | L24: =COUNTIFS($AA:$AA,$G24,$AC:$AC,"Conference Paper") -> 0 | M24: =N24-SUM(H24:L24) -> 2 | N24: =E11 -> 15 | AA24: Mariotti-Celis M.S. | AB24: 2024 | AC24: Article
G25: =B12 -> Henríquez-Olguín C. | H25: =COUNTIFS($AA:$AA,$G25,$AC:$AC,"Article") -> 10 | I25: =COUNTIFS($AA:$AA,$G25,$AC:$AC,"Review") -> 3 | J25: =COUNTIFS($AA:$AA,$G25,$AC:$AC,"Letter") -> 0 | K25: =COUNTIFS($AA:$AA,$G25,$AC:$AC,"Chapter") -> 0 | L25: =COUNTIFS($AA:$AA,$G25,$AC:$AC,"Conference Paper") -> 0 | M25: =N25-SUM(H25:L25) -> 0 | N25: =E12 -> 13 | AA25: Orellana-Donoso M. | AB25: 2024 | AC25: Review
G26: =B13 -> López-Arana S. | H26: =COUNTIFS($AA:$AA,$G26,$AC:$AC,"Article") -> 10 | I26: =COUNTIFS($AA:$AA,$G26,$AC:$AC,"Review") -> 1 | J26: =COUNTIFS($AA:$AA,$G26,$AC:$AC,"Letter") -> 2 | K26: =COUNTIFS($AA:$AA,$G26,$AC:$AC,"Chapter") -> 0 | L26: =COUNTIFS($AA:$AA,$G26,$AC:$AC,"Conference Paper") -> 0 | M26: =N26-SUM(H26:L26) -> 0 | N26: =E13 -> 13 | AA26: Yanine F.F. | AB26: 2024 | AC26: Article
G27: =B14 -> Fernández-Verdejo R. | H27: =COUNTIFS($AA:$AA,$G27,$AC:$AC,"Article") -> 6 | I27: =COUNTIFS($AA:$AA,$G27,$AC:$AC,"Review") -> 3 | J27: =COUNTIFS($AA:$AA,$G27,$AC:$AC,"Letter") -> 1 | K27: =COUNTIFS($AA:$AA,$G27,$AC:$AC,"Chapter") -> 0 | L27: =COUNTIFS($AA:$AA,$G27,$AC:$AC,"Conference Paper") -> 0 | M27: =N27-SUM(H27:L27) -> 2 | N27: =E14 -> 12 | AA27: Santos M. | AB27: 2024 | AC27: Article
G28: =B15 -> Mariotti-Celis M.S. | H28: =COUNTIFS($AA:$AA,$G28,$AC:$AC,"Article") -> 12 | I28: =COUNTIFS($AA:$AA,$G28,$AC:$AC,"Review") -> 0 | J28: =COUNTIFS($AA:$AA,$G28,$AC:$AC,"Letter") -> 0 | K28: =COUNTIFS($AA:$AA,$G28,$AC:$AC,"Chapter") -> 0 | L28: =COUNTIFS($AA:$AA,$G28,$AC:$AC,"Conference Paper") -> 0 | M28: =N28-SUM(H28:L28) -> 0 | N28: =E15 -> 12 | AA28: Henríquez-Olguín C. | AB28: 2025 | AC28: Article
G29: =B16 -> Cancino-López J. | H29: =COUNTIFS($AA:$AA,$G29,$AC:$AC,"Article") -> 6 | I29: =COUNTIFS($AA:$AA,$G29,$AC:$AC,"Review") -> 3 | J29: =COUNTIFS($AA:$AA,$G29,$AC:$AC,"Letter") -> 1 | K29: =COUNTIFS($AA:$AA,$G29,$AC:$AC,"Chapter") -> 0 | L29: =COUNTIFS($AA:$AA,$G29,$AC:$AC,"Conference Paper") -> 0 | M29: =N29-SUM(H29:L29) -> 1 | N29: =E16 -> 11 | AA29: Lucero-Mora J. | AB29: 2024 | AC29: Article
AA30: Yanine F.F. | AB30: 2025 | AC30: Article
AA31: Morales-Guevara R. | AB31: 2024 | AC31: Article
AA32: Mujika I. | AB32: 2025 | AC32: Article
AA33: Díaz-Castro F. | AB33: 2024 | AC33: Article
AA34: Tuñón-Suárez M. | AB34: 2024 | AC34: Article
AA35: Cancino J. | AB35: 2024 | AC35: Article
AA36: Figueroa A.M. | AB36: 2024 | AC36: Article
AA37: Gutiérrez J. | AB37: 2024 | AC37: Article
AA38: Zbinden-Foncea H. | AB38: 2024 | AC38: Article
AA39: Henríquez-Olguín C. | AB39: 2024 | AC39: Article
AA40: Castro-Sepúlveda M. | AB40: 2024 | AC40: Article
...

Sheet Publicaciones unificadas
A1: # | B1: Título | C1: Año | D1: Tipo | E1: Revista | F1: N° autores UFT | G1: Autores UFT (autoría / coautoría) | H1: DOI | I1: N° autores (total) | J1: % part. UFT
A2: 1 | B2: "Writing from no language": Henri Michaux's signs in motion. | C2: 2025 | D2: Article | E2: Logos: Revista de Linguistica, Filosofia y Literatura | F2: =IF($G2="",0,LEN($G2)-LEN(SUBSTITUTE($G2,"|",""))+1) -> 1 | G2: Kobayashi M.A. | H2: 10.15443/RL3502 | I2: 1 | J2: =IFERROR(F2/I2,"") -> 1
A3: 2 | B3: A New Approach to Evaluating Diversity and Difficulty in Procedurally Generated 2D Platformer Game Levels Through the Relationship Between Structural Metrics and Game Mechanic Constraints in Intelligent Agents | C3: 2025 | D3: Conference Paper | E3: Proceedings - International Conference of the Chilean Computer Science Society, SCCC | F3: =IF($G3="",0,LEN($G3)-LEN(SUBSTITUTE($G3,"|",""))+1) -> 2 | G3: Perez S. | Rojas D. | H3: 10.1109/SCCC67219.2025.11420775 | I3: 2 | J3: =IFERROR(F3/I3,"") -> 1
A4: 3 | B4: A ORDENAÇÃO DOS DESEJOS POR MEIO DA PRÁTICA DAS VIRTUDES E O DESENVOLVIMENTO DO RACIOCÍNIO PRÁTICO: UMA PROPOSTA PARA O FLORESCIMENTO HUMANO BASEADA NO PENSAMENTO DE ALASDAIR MACINTYRE | C4: 2025 | D4: Article | E4: Kriterion (Brazil) | F4: =IF($G4="",0,LEN($G4)-LEN(SUBSTITUTE($G4,"|",""))+1) -> 1 | G4: Rugeles F.L. | H4: 10.1590/0100-512X2025n16202flr | I4: 1 | J4: =IFERROR(F4/I4,"") -> 1
A5: 4 | B5: A Study of Software Architects’ Cognitive Approaches: Kolb’s Learning Styles Inventory in Action | C5: 2025 | D5: Conference Paper | E5: Communications in Computer and Information Science | F5: =IF($G5="",0,LEN($G5)-LEN(SUBSTITUTE($G5,"|",""))+1) -> 1 | G5: Hidalgo M. | H5: 10.1007/978-3-031-75147-9_16 | I5: 3 | J5: =IFERROR(F5/I5,"") -> 0.33333333
A6: 5 | B6: A Sub-Hourly Precipitation Dataset from a Pluviographic Network in Central Chile | C6: 2025 | D6: Article | E6: Data | F6: =IF($G6="",0,LEN($G6)-LEN(SUBSTITUTE($G6,"|",""))+1) -> 1 | G6: Paredes R. | H6: 10.3390/data10070095 | I6: 10 | J6: =IFERROR(F6/I6,"") -> 0.1
A7: 6 | B7: A Systematic Review and Meta-Analysis on the Prevalence of Variants in the Pancreaticobiliary Duct Junction and Its Association with Cancer | C7: 2025 | D7: Review | E7: Biomedicines | F7: =IF($G7="",0,LEN($G7)-LEN(SUBSTITUTE($G7,"|",""))+1) -> 1 | G7: Orellana-Donoso M. | H7: 10.3390/biomedicines13051039 | I7: 13 | J7: =IFERROR(F7/I7,"") -> 0.076923077
A8: 7 | B8: A Systematic Review of Anatomical Variations of the Inferior Thyroid Artery: Clinical and Surgical Considerations | C8: 2025 | D8: Review | E8: Diagnostics | F8: =IF($G8="",0,LEN($G8)-LEN(SUBSTITUTE($G8,"|",""))+1) -> 1 | G8: Orellana-Donoso M. | H8: 10.3390/diagnostics15151858 | I8: 12 | J8: =IFERROR(F8/I8,"") -> 0.083333333
A9: 8 | B9: A Systematic Review with a Meta-Analysis of the Morphological Variants of the Corpus Callosum: Related Neurocognitive Clinical Implications | C9: 2025 | D9: Review | E9: World Neurosurgery | F9: =IF($G9="",0,LEN($G9)-LEN(SUBSTITUTE($G9,"|",""))+1) -> 1 | G9: Orellana-Donoso M. | H9: 10.1016/j.wneu.2025.124317 | I9: 14 | J9: =IFERROR(F9/I9,"") -> 0.071428571
A10: 9 | B10: A comprehensive review of smart energy management systems for photovoltaic power generation utilizing the internet of things | C10: 2025 | D10: Review | E10: Unconventional Resources | F10: =IF($G10="",0,LEN($G10)-LEN(SUBSTITUTE($G10,"|",""))+1) -> 1 | G10: Yanine F.F. | H10: 10.1016/j.uncres.2025.100197 | I10: 3 | J10: =IFERROR(F10/I10,"") -> 0.33333333
A11: 10 | B11: A gender-integrated biopsychosocial model to understand cardiovascular risk in women working under environmental hazards: the case of chronic intermittent hypoxia | C11: 2025 | D11: Short Survey | E11: Frontiers in Public Health | F11: =IF($G11="",0,LEN($G11)-LEN(SUBSTITUTE($G11,"|",""))+1) -> 1 | G11: Lang M. | H11: 10.3389/fpubh.2025.1672503 | I11: 4 | J11: =IFERROR(F11/I11,"") -> 0.25
A12: 11 | B12: A map of collective pedagogical content knowledge as a basis for studying the development of biology teachers’ personal PCK of evolution | C12: 2025 | D12: Article | E12: International Journal of Science Education | F12: =IF($G12="",0,LEN($G12)-LEN(SUBSTITUTE($G12,"|",""))+1) -> 1 | G12: Santibáñez D. | H12: 10.1080/09500693.2024.2381841 | I12: 7 | J12: =IFERROR(F12/I12,"") -> 0.14285714
A13: 12 | B13: A review of IoT-based smart energy solutions for photovoltaic systems | C13: 2025 | D13: Article | E13: Electrical Engineering | F13: =IF($G13="",0,LEN($G13)-LEN(SUBSTITUTE($G13,"|",""))+1) -> 1 | G13: Yanine F.F. | H13: 10.1007/s00202-025-03312-3 | I13: 3 | J13: =IFERROR(F13/I13,"") -> 0.33333333
... A131: 130 | B131: INSTRUMENTS FOR MEASURING ANXIETY IN DENTAL STUDENTS: A BIBLIOMETRIC ANALYSIS | C131: 2025 | D131: Article | E131: Journal of Oral Research | F131: =IF($G131="",0,LEN($G131)-LEN(SUBSTITUTE($G131,"|",""))+1) -> 4 | G131: Zamorano S. | Caro J.C. | Ponce N. | Moya P. | H131: 10.17126/joralres.2025.020 | I131: 4 | J131: =IFERROR(F131/I131,"") -> 1
A132: 131 | B132: Immediate loading of definitive restorations in partially edentulous patients requiring an implant-supported prosthesis: A scoping review | C132: 2025 | D132: Review | E132: Journal of Prosthetic Dentistry | F132: 1 | G132: Strauss F.J. | H132: 10.1016/j.prosdent.2024.04.013 | I132: 7 | J132: =IFERROR(F132/I132,"") -> 0.14285714
A133: 132 | B133: Immunomodulation and Immunotherapy for Patients with Prostate Cancer: An Up-to-Date Review | C133: 2025 | D133: Review | E133: Biomedicines | F133: =IF($G133="",0,LEN($G133)-LEN(SUBSTITUTE($G133,"|",""))+1) -> 1 | G133: Murray N.P. | H133: 10.3390/biomedicines13051179 | I133: 1 | J133: =IFERROR(F133/I133,"") -> 1
A134: 133 | B134: Immunotherapy-Related Pancreatitis: A Case Series of 8 Patients from a High-Volume Oncology Centre | C134: 2025 | D134: Article | E134: Case Reports in Oncology | F134: =IF($G134="",0,LEN($G134)-LEN(SUBSTITUTE($G134,"|",""))+1) -> 1 | G134: San Martín T. | H134: 10.1159/000548016 | I134: 5 | J134: =IFERROR(F134/I134,"") -> 0.2
A135: 134 | B135: Impact of Teleworking on Work-Related and Home-Related Stress at During the First Global Lockdown–The International COVISTRESS Study | C135: 2025 | D135: Article | E135: Brain and Behavior | F135: =IF($G135="",0,LEN($G135)-LEN(SUBSTITUTE($G135,"|",""))+1) -> 1 | G135: Avilès Dorlhiac R. | H135: 10.1002/brb3.70592 | I135: 18 | J135: =IFERROR(F135/I135,"") -> 0.055555556
A136: 135 | B136: Impact of strength-based video-feedback intervention on maternal sensitivity in mother–infant dyads with maternal depressive symptoms | C136: 2025 | D136: Article | E136: Infant Mental Health Journal | F136: =IF($G136="",0,LEN($G136)-LEN(SUBSTITUTE($G136,"|",""))+1) -> 1 | G136: Muzard A. | H136: 10.1002/imhj.22154 | I136: 8 | J136: =IFERROR(F136/I136,"") -> 0.125
A137: 136 | B137: In situ simulation in the intensive care unit: A phenomenological study of staff experiences | C137: 2025 | D137: Article | E137: Perfusion (United Kingdom) | F137: =IF($G137="",0,LEN($G137)-LEN(SUBSTITUTE($G137,"|",""))+1) -> 6 | G137: Ferre A. | Giglio A. | Van Sint Jan N. | Benites M.H. | Dreyse J. | Hasbun P. | H137: 10.1177/02676591241272058 | I137: 9 | J137: =IFERROR(F137/I137,"") -> 0.66666667
A138: 137 | B138: In vivo experimental study comparing alveolar ridge preservation versus guided bone regeneration after unassisted socket healing at intact and damaged sites in narrow alveolar ridges | C138: 2025 | D138: Article | E138: Journal of Periodontology | F138: =IF($G138="",0,LEN($G138)-LEN(SUBSTITUTE($G138,"|",""))+1) -> 1 | G138: Strauss F.J. | H138: 10.1002/JPER.24-0125 | I138: 6 | J138: =IFERROR(F138/I138,"") -> 0.16666667
A139: 138 | B139: Inclusion of ΑVβ3 integrin into extracellular vesicles in a caveolin-1 tyrosine-14- phosphorylation dependent manner and subsequent transfer to recipient melanoma cells promotes migration, invasion and metastasis | C139: 2025 | D139: Article | E139: System.Xml.XmlElement | F139: =IF($G139="",0,LEN($G139)-LEN(SUBSTITUTE($G139,"|",""))+1) -> 1 | G139: Simón L. | H139: 10.1186/s12964-025-02131-0 | I139: 11 | J139: =IFERROR(F139/I139,"") -> 0.090909091
A140: 139 | B140: Infectious morbidity and white blood cell count associated with grade repetition and school absenteeism | C140: 2025 | D140: Article | E140: Acta Paediatrica, International Journal of Paediatrics | F140: =IF($G140="",0,LEN($G140)-LEN(SUBSTITUTE($G140,"|",""))+1) -> 1 | G140: López-Arana S. | H140: 10.1111/apa.17513 | I140: 6 | J140: =IFERROR(F140/I140,"") -> 0.16666667
A141: 140 | B141: Influence of Iodine Substitutions on the Photophysical Properties of Rhenium(I) Tricarbonyl Complexes With Pyridine Schiff Base (PSB-IHB) | C141: 2025 | D141: Article | E141: International Journal of Quantum Chemistry | F141: =IF($G141="",0,LEN($G141)-LEN(SUBSTITUTE($G141,"|",""))+1) -> 1 | G141: Morales-Guevara R. | H141: 10.1002/qua.70005 | I141: 4 | J141: =IFERROR(F141/I141,"") -> 0.25
A142: 141 | B142: Inhibition of the formation of 2-amino-1-methyl-6-phenylimidazo[4,5-b]pyridine (PhIP) and 2-amino-3,8-dimethyl-3H-imidazo[4,5-f]quinoxaline (MeIQx) by phenolics in model systems and beef patties | C142: 2025 | D142: Article | E142: Food Chemistry | F142: =IF($G142="",0,LEN($G142)-LEN(SUBSTITUTE($G142,"|",""))+1) -> 1 | G142: Mariotti-Cellis M.S. | H142: 10.1016/j.foodchem.2025.144091 | I142: 6 | J142: =IFERROR(F142/I142,"") -> 0.16666667
A143: 142 | B143: Integral training for food sustainability: a pending subject in Latin America | C143: 2025 | D143: Article | E143: Revista Chilena de Nutricion | F143: =IF($G143="",0,LEN($G143)-LEN(SUBSTITUTE($G143,"|",""))+1) -> 1 | G143: López-Arana S. | H143: 10.64159/RCHNUT-52-5-10 | I143: 3 | J143: =IFERROR(F143/I143,"") -> 0.33333333
A144: 143 | B144: Integrated strategies for reducing acrylamide, 5-HMF, and furan in colored native and commercial potato chips: Synergistic effects of nutrient solution conductivity and pre-frying treatments | C144: 2025 | D144: Article | E144: LWT | F144: =IF($G144="",0,LEN($G144)-LEN(SUBSTITUTE($G144,"|",""))+1) -> 1 | G144: Mariotti-Celis M.S. | H144: 10.1016/j.lwt.2025.118398 | I144: 7 | J144: =IFERROR(F144/I144,"") -> 0.14285714
... A234: 233 | B234: Severe middle childhood acne treated with isotretinoin | C234: 2025 | D234: Article | E234: Piel | F234: =IF($G234="",0,LEN($G234)-LEN(SUBSTITUTE($G234,"|",""))+1) -> 1 | G234: Hartmann D. | H234: 10.1016/j.piel.2024.04.006 | I234: 6 | J234: =IFERROR(F234/I234,"") -> 0.16666667
A235: 234 | B235: Severe obesity and menopause symptoms are associated with cognitive impairment in postmenopausal women from Latin America | C235: 2025 | D235: Article | E235: Climacteric | F235: 1 | G235: Aedo S. | H235: 10.1080/13697137.2025.2491637 | I235: 18 | J235: =IFERROR(F235/I235,"") -> 0.055555556
A236: 235 | B236: Sexual Dimorphism in the Atlas Vertebra of Normal and Overweight Patients with its Possible Surgical Implications | C236: 2025 | D236: Article | E236: World Neurosurgery | F236: =IF($G236="",0,LEN($G236)-LEN(SUBSTITUTE($G236,"|",""))+1) -> 1 | G236: Orellana-Donoso M. | H236: 10.1016/j.wneu.2025.124531 | I236: 11 | J236: =IFERROR(F236/I236,"") -> 0.090909091
A237: 236 | B237: Should we move beyond the concept of fluid responsiveness? | C237: 2025 | D237: Letter | E237: Intensive Care Medicine | F237: =IF($G237="",0,LEN($G237)-LEN(SUBSTITUTE($G237,"|",""))+1) -> 4 | G237: Giglio Jimenez A. | Tovar W. | Pedreros C. | Ferre A. | H237: 10.1007/s00134-025-07787-3 | I237: 4 | J237: =IFERROR(F237/I237,"") -> 1
A238: 237 | B238: Skeletal muscle Rac1 mediates exercise training adaptations towards muscle glycogen resynthesis and protein synthesis | C238: 2025 | D238: Article | E238: Redox Biology | F238: =IF($G238="",0,LEN($G238)-LEN(SUBSTITUTE($G238,"|",""))+1) -> 1 | G238: Henríquez-Olguín C. | H238: 10.1016/j.redox.2025.103844 | I238: 21 | J238: =IFERROR(F238/I238,"") -> 0.047619048
A239: 238 | B239: Sleep Restriction and Weekend Sleep Compensation Relate to Eating Behavior in School-Aged Children | C239: 2025 | D239: Article | E239: Nature and Science of Sleep | F239: =IF($G239="",0,LEN($G239)-LEN(SUBSTITUTE($G239,"|",""))+1) -> 1 | G239: Gutierrez M. | H239: 10.2147/NSS.S509636 | I239: 5 | J239: =IFERROR(F239/I239,"") -> 0.2
A240: 239 | B240: Snapshot of a Decade: Idiopathic Inflammatory Myopathies in Chile - A 10-Year Short Report | C240: 2025 | D240: Article | E240: Journal of Clinical Rheumatology | F240: =IF($G240="",0,LEN($G240)-LEN(SUBSTITUTE($G240,"|",""))+1) -> 1 | G240: Giglio A. | H240: 10.1097/RHU.0000000000002230 | I240: 5 | J240: =IFERROR(F240/I240,"") -> 0.2
A241: 240 | B241: Social Media and Plastic Surgery, the Good, the Bad, and Where are We Going? | C241: 2025 | D241: Review | E241: Aesthetic Plastic Surgery | F241: =IF($G241="",0,LEN($G241)-LEN(SUBSTITUTE($G241,"|",""))+1) -> 6 | G241: Maldonado J D. | Arriagada I C. | Conejero R A. | Covarrubias C P. | Doña V J. | Hurtado D M.J. | H241: 10.1007/s00266-025-04748-5 | I241: 6 | J241: =IFERROR(F241/I241,"") -> 1
A242: 241 | B242: Social and health factors affecting work-related accidents among older informal workers in Chile: A probit model analysis based on CASEN 2022 | C242: 2025 | D242: Article | E242: Social Sciences and Humanities Open | F242: =IF($G242="",0,LEN($G242)-LEN(SUBSTITUTE($G242,"|",""))+1) -> 1 | G242: Arenas-Massa A. | H242: 10.1016/j.ssaho.2025.102231 | I242: 2 | J242: =IFERROR(F242/I242,"") -> 0.5
A243: 242 | B243: Soft-tissue volume augmentation during early, delayed, and late dental implant therapy: A systematic review and meta-analysis on professionally determined esthetics and self-reported patient satisfaction on esthetics | C243: 2025 | D243: Review | E243: Periodontology 2000 | F243: =IF($G243="",0,LEN($G243)-LEN(SUBSTITUTE($G243,"|",""))+1) -> 1 | G243: Strauss F.J. | H243: 10.1111/prd.12628 | I243: 6 | J243: =IFERROR(F243/I243,"") -> 0.16666667
A244: 243 | B244: Some Considerations on the Psychological Experience of Time in Friendship According to Thomas Aquinas | C244: 2025 | D244: Article | E244: Scripta Mediaevalia | F244: =IF($G244="",0,LEN($G244)-LEN(SUBSTITUTE($G244,"|",""))+1) -> 1 | G244: Muszalski H. | H244: 10.48162/rev.35.048 | I244: 1 | J244: =IFERROR(F244/I244,"") -> 1
A245: 244 | B245: Submaximal Accentuated Eccentric Jump Training Improves Punching Performance and Countermovement Jump Force–Time Variables in Amateur Boxers | C245: 2025 | D245: Article | E245: Applied Sciences (Switzerland) | F245: =IF($G245="",0,LEN($G245)-LEN(SUBSTITUTE($G245,"|",""))+1) -> 1 | G245: Cancino-López J. | H245: 10.3390/app15147873 | I245: 11 | J245: =IFERROR(F245/I245,"") -> 0.090909091
A246: 245 | B246: Subtalar joint revision arthrodesis due to non-union: a case report | C246: 2025 | D246: Article | E246: Revista Medica Clinica Las Condes | F246: =IF($G246="",0,LEN($G246)-LEN(SUBSTITUTE($G246,"|",""))+1) -> 5 | G246: Verschae G. | Val V. | Alba V. | Pavez S. | Cid N. | H246: 10.1016/j.rmclc.2025.01.002 | I246: 6 | J246: =IFERROR(F246/I246,"") -> 0.83333333
...

Sheet Informe Cienciométrico (2)
A1: Informe Cienciométrico — Producción Científica UFT
A2: Base de datos: hoja «Publicaciones unificadas» · Período 2024–2025 · Análisis bibliométrico de producción, fuentes, autoría y colaboración
A4: Publicaciones totales | D4: Publicaciones 2025 | G4: Publicaciones 2024 | J4: Fuentes / revistas distintas
A5: =COUNTA(PublicacionesUnicas[Título]) -> 589 | D5: =COUNTIF(PublicacionesUnicas[Año],2025) -> 317 | G5: =COUNTIF(PublicacionesUnicas[Año],2024) -> 271 | J5: {=SUMPRODUCT((PublicacionesUnicas[Revista]<>"")/COUNTIF(PublicacionesUnicas[Revista],PublicacionesUnicas[Revista]&""))} -> 368
A7: % participación UFT (promedio) | D7: Autores por publicación (prom.) | G7: Autores UFT por publicación (prom.) | J7: Investigadores UFT distintos (aprox.)
A8: =AVERAGE(PublicacionesUnicas[% part. UFT]) -> 0.38686157 | D8: =AVERAGE(PublicacionesUnicas[N° autores (total)]) -> 6.8095238 | G8: =AVERAGE(PublicacionesUnicas[N° autores UFT]) -> 1.4601019 | J8: 397
A11: 1. Producción anual
A12: Año | B12: Publicaciones | C12: % del total
A13: 2024 | B13: =COUNTIF(PublicacionesUnicas[Año],2024) -> 271 | C13: =B13/$B$15 -> 0.46088435
A14: 2025 | B14: =COUNTIF(PublicacionesUnicas[Año],2025) -> 317 | C14: =B14/$B$15 -> 0.53911565
A15: Total | B15: =SUM(B13:B14) -> 588 | C15: =B15/$B$15 -> 1
A28: 2. Tipología documental
A29: Tipo de documento | B29: Publicaciones | C29: % del total
A30: Article | B30: =COUNTIF(PublicacionesUnicas[Tipo],A30) -> 412 | C30: =B30/$B$40 -> 0.70068027
A31: Review | B31: =COUNTIF(PublicacionesUnicas[Tipo],A31) -> 103 | C31: =B31/$B$40 -> 0.17517007
A32: Letter | B32: =COUNTIF(PublicacionesUnicas[Tipo],A32) -> 21 | C32: =B32/$B$40 -> 0.035714286
A33: Conference Paper | B33: =COUNTIF(PublicacionesUnicas[Tipo],A33) -> 14 | C33: =B33/$B$40 -> 0.023809524
A34: Note | B34: =COUNTIF(PublicacionesUnicas[Tipo],A34) -> 6 | C34: =B34/$B$40 -> 0.010204082
A35: Editorial | B35: =COUNTIF(PublicacionesUnicas[Tipo],A35) -> 7 | C35: =B35/$B$40 -> 0.011904762
A36: Chapter | B36: =COUNTIF(PublicacionesUnicas[Tipo],A36) -> 17 | C36: =B36/$B$40 -> 0.028911565
A37: Short Survey | B37: =COUNTIF(PublicacionesUnicas[Tipo],A37) -> 3 | C37: =B37/$B$40 -> 0.0051020408
A38: Erratum | B38: =COUNTIF(PublicacionesUnicas[Tipo],A38) -> 4 | C38: =B38/$B$40 -> 0.0068027211
A39: Book | B39: =COUNTIF(PublicacionesUnicas[Tipo],A39) -> 1 | C39: =B39/$B$40 -> 0.0017006803
A40: Total | B40: =SUM(B30:B39) -> 588 | C40: =B40/$B$40 -> 1
A48: 3. Fuentes más productivas (Top 15 revistas)
A49: Revista | B49: Publicaciones
A50: Revista Medica Clinica Las Condes | B50: =COUNTIF(PublicacionesUnicas[Revista],A50) -> 35
A51: Diagnostics | B51: =COUNTIF(PublicacionesUnicas[Revista],A51) -> 10
A52: Revista Chilena de Nutricion | B52: =COUNTIF(PublicacionesUnicas[Revista],A52) -> 10
A53: International Journal of Sports Physiology and Performance | B53: =COUNTIF(PublicacionesUnicas[Revista],A53) -> 10
A54: Antioxidants | B54: =COUNTIF(PublicacionesUnicas[Revista],A54) -> 9
A55: Andes Pediatrica | B55: =COUNTIF(PublicacionesUnicas[Revista],A55) -> 8
A56: International Journal of Molecular Sciences | B56: =COUNTIF(PublicacionesUnicas[Revista],A56) -> 7
A57: Journal of Clinical Medicine | B57: =COUNTIF(PublicacionesUnicas[Revista],A57) -> 7
A58: Piel | B58: =COUNTIF(PublicacionesUnicas[Revista],A58) -> 6
A59: Obesity Surgery | B59: =COUNTIF(PublicacionesUnicas[Revista],A59) -> 5
A60: Critical Care | B60: =COUNTIF(PublicacionesUnicas[Revista],A60) -> 5
A61: Scientific Reports | B61: =COUNTIF(PublicacionesUnicas[Revista],A61) -> 5
... A64: Frontiers in Psychology | B64: =COUNTIF(PublicacionesUnicas[Revista],A64) -> 4
A72: 4. Investigadores UFT más productivos (Top 15)
...

Sheet Informe Cienciométrico
A1: Informe Cienciométrico — Producción Científica UFT
A2: Base de datos: hoja «Publicaciones unificadas» · Período 2024–2025 · Análisis bibliométrico de producción, fuentes, autoría y colaboración
A4: Publicaciones totales | D4: Publicaciones 2025 | G4: Publicaciones 2024 | J4: Fuentes / revistas distintas
A5: =COUNTA(PublicacionesUnicas[Título]) -> 589 | D5: =COUNTIF(PublicacionesUnicas[Año],2025) -> 317 | G5: =COUNTIF(PublicacionesUnicas[Año],2024) -> 271 | J5: {=SUMPRODUCT((PublicacionesUnicas[Revista]<>"")/COUNTIF(PublicacionesUnicas[Revista],PublicacionesUnicas[Revista]&""))} -> 368
A7: % participación UFT (promedio) | D7: Autores por publicación (prom.) | G7: Autores UFT por publicación (prom.) | J7: Investigadores UFT distintos (aprox.)
A8: =AVERAGE(PublicacionesUnicas[% part. UFT]) -> 0.38686157 | D8: =AVERAGE(PublicacionesUnicas[N° autores (total)]) -> 6.8095238 | G8: =AVERAGE(PublicacionesUnicas[N° autores UFT]) -> 1.4601019 | J8: 397
A11: 1. Producción anual
A12: Año | B12: Publicaciones | C12: % del total
A13: 2024 | B13: =COUNTIF(PublicacionesUnicas[Año],2024) -> 271 | C13: =B13/$B$15 -> 0.46088435
A14: 2025 | B14: =COUNTIF(PublicacionesUnicas[Año],2025) -> 317 | C14: =B14/$B$15 -> 0.53911565
A15: Total | B15: =SUM(B13:B14) -> 588 | C15: =B15/$B$15 -> 1
A28: 2. Tipología documental
A29: Tipo de documento | B29: Publicaciones | C29: % del total
A30: Article | B30: =COUNTIF(PublicacionesUnicas[Tipo],A30) -> 412 | C30: =B30/$B$40 -> 0.70068027
A31: Review | B31: =COUNTIF(PublicacionesUnicas[Tipo],A31) -> 103 | C31: =B31/$B$40 -> 0.17517007
A32: Letter | B32: =COUNTIF(PublicacionesUnicas[Tipo],A32) -> 21 | C32: =B32/$B$40 -> 0.035714286
A33: Conference Paper | B33: =COUNTIF(PublicacionesUnicas[Tipo],A33) -> 14 | C33: =B33/$B$40 -> 0.023809524
A34: Note | B34: =COUNTIF(PublicacionesUnicas[Tipo],A34) -> 6 | C34: =B34/$B$40 -> 0.010204082
A35: Editorial | B35: =COUNTIF(PublicacionesUnicas[Tipo],A35) -> 7 | C35: =B35/$B$40 -> 0.011904762
A36: Chapter | B36: =COUNTIF(PublicacionesUnicas[Tipo],A36) -> 17 | C36: =B36/$B$40 -> 0.028911565
A37: Short Survey | B37: =COUNTIF(PublicacionesUnicas[Tipo],A37) -> 3 | C37: =B37/$B$40 -> 0.0051020408
A38: Erratum | B38: =COUNTIF(PublicacionesUnicas[Tipo],A38) -> 4 | C38: =B38/$B$40 -> 0.0068027211
A39: Book | B39: =COUNTIF(PublicacionesUnicas[Tipo],A39) -> 1 | C39: =B39/$B$40 -> 0.0017006803
A40: Total | B40: =SUM(B30:B39) -> 588 | C40: =B40/$B$40 -> 1
A48: 3. Fuentes más productivas (Top 15 revistas)
A49: Revista | B49: Publicaciones
A50: Revista Medica Clinica Las Condes | B50: =COUNTIF(PublicacionesUnicas[Revista],A50) -> 35
A51: Diagnostics | B51: =COUNTIF(PublicacionesUnicas[Revista],A51) -> 10
A52: Revista Chilena de Nutricion | B52: =COUNTIF(PublicacionesUnicas[Revista],A52) -> 10
A53: International Journal of Sports Physiology and Performance | B53: =COUNTIF(PublicacionesUnicas[Revista],A53) -> 10
A54: Antioxidants | B54: =COUNTIF(PublicacionesUnicas[Revista],A54) -> 9
A55: Andes Pediatrica | B55: =COUNTIF(PublicacionesUnicas[Revista],A55) -> 8
A56: International Journal of Molecular Sciences | B56: =COUNTIF(PublicacionesUnicas[Revista],A56) -> 7
A57: Journal of Clinical Medicine | B57: =COUNTIF(PublicacionesUnicas[Revista],A57) -> 7
A58: Piel | B58: =COUNTIF(PublicacionesUnicas[Revista],A58) -> 6
A59: Obesity Surgery | B59: =COUNTIF(PublicacionesUnicas[Revista],A59) -> 5
A60: Critical Care | B60: =COUNTIF(PublicacionesUnicas[Revista],A60) -> 5
A61: Scientific Reports | B61: =COUNTIF(PublicacionesUnicas[Revista],A61) -> 5
... A64: Frontiers in Psychology | B64: =COUNTIF(PublicacionesUnicas[Revista],A64) -> 4
A72: 4. Investigadores UFT más productivos (Top 15)
...

Sheet Publicaciones_UFT_detalle (2)
A1: Autores finis terrae afiliados | B1: Título | C1: Authors | D1: Year | E1: Full date | F1: Scopus Source title | G1: Volume | H1: Issue | I1: Pages | J1: ISSN | K1: Publisher | L1: Language | M1: CiteScore (publication year) | N1: CiteScore percentile (publication year) * | O1: SJR (publication year) | P1: DOI | Q1: Publication type | R1: EID | S1: Institutions | T1: Scopus Affiliation IDs | U1: Scopus Affiliation names | V1: Country/Region
A2: Mujika I. | B2: Using artificial intelligence for exercise prescription in personalised health promotion: A critical evaluation of OpenAI’s GPT-4 model | C2: Dergaa, I.| Saad, H.B.| El Omri, A.| Glenn, J.M.| Clark, C.C.T.| Washif, J.A.| Guelmami, N.| Hammouda, O.| Al-Horani, R.A.| Reynoso-Sánchez, L.F.| Romdhani, M.| Paineiras-Domingos, L.L.| Vancini, R.L.| Taheri, M.| Mataruna-Dos-Santos, L.J.| Trabelsi, K.| Chtourou, H.| Zghibi, M.| Eken, Ö.| Swed, S.| Aissa, M.B.| Shawki, H.H.| El-Seedi, H.R.| Mujika, I.| Seiler, S.| Zmijewski, P.| Pyne, D.B.| Knechtle, B.| Asif, I.M.| Drezner, J.A.| Sandbakk, Ø.| Chamari, K. | D2: 2024 | E2: 45292 | F2: Biology of Sport | G2: 42 | H2: 2 | I2: 221-241 | J2: ISSN-0860021X | K2: Institute of Sport | L2: English | M2: 9.4 | N2: 3.0 | O2: 1645 | P2: 10.5114/biolsport.2024.133661 | Q2: Article | R2: 2-s2.0-85188146191 | S2: Hamad Medical Corporation| Jiangsu University| University of Canberra| University of Aleppo| University of Zurich| Universidad Finis Terrae| University of Genoa| Jozef Pilsudski University of Physical Education in Warsaw| University of Alabama at Birmingham| University of Manouba| Islamic University of Madinah| University of Agder| Birmingham City University| University of Sousse| Canadian University Dubai| Nagoya City University| University of Tehran| Université Paris Nanterre| Yarmouk University| Norwegian University of Science and Technology| Coventry University| Universidade Federal da Bahia| Inonu University| University of the Basque Country| University of Jendouba| University of Sfax| Universidade Federal do Espírito Santo| University of Washington | T2: 60264454| 60064746| 60091664| 60279855| 60044627| 60058071| 60060593| 60072743| 60330445| 60100434| 60017326| 60090678| 60025153| 60017338| 60206635| 60042547| 60044065| 122712524| 60013710| 60028426| 60022927| 60105484| 60015585| 60072763| 60072762| 60004321| 60105081| 60017482| 60027856| 60105368| 60080184| 60010960| 60022193| 60012614| 60027086| 60119065| 60028548| 60015481| 60013141| 60070316| 60274653 | U2: Primary Health Care Corporation| University of Sfax| Institut Supérieur du Sport et de l'Education Physique de Sfax| Institut Supérieur de Sport et de l´Education Physique du Kef| Hopital Farhat Hached Sousse| Université de Sousse| Faculty of Medicine sousse| Hamad Medical Corporation| Neurotrack Technologies, Inc.| Birmingham City University| Coventry University| Institut Sukan Negara Malaysia| Università degli Studi di Genova| Université Paris Nanterre| Laboratoire Interdisciplinaire en Neurosciences, Physiologie et Psychologie : Activité Physique, Santé et Apprentissages - LINP2| Faculty of Medicine of Sfax| Yarmouk University| Autonomous University of Occident| Universidade Federal da Bahia| Universidade Federal do Espírito Santo| University of Tehran| Canadian University Dubai| Inönü Üniversitesi| Aleppo Faculty of Medicine| University of Aleppo| Nagoya City University Graduate School of Medical Sciences| Islamic University of Madinah| Jiangsu University| Universidad del Pais Vasco| Universidad Finis Terrae| Universitetet i Agder| Akademia Wychowania Fizycznego Józefa Piłsudskiego w Warszawie| University of Canberra| Universität Zürich| The University of Alabama at Birmingham| UAB Department of Family and Community Medicine| University of Washington School of Medicine| University of Washington| Norges Teknisk-Naturvitenskapelige Universitet| Université de la Manouba| Institut Supérieur du Sport et de l'Education Physique de Ksar-Saïd | V2: United Arab Emirates| Chile| United Kingdom| Mexico| Spain| Japan| Syrian Arab Republic| Italy| France| Brazil| Qatar| Norway| China| Tunisia| Poland| Jordan| United States| Saudi Arabia| Turkey| Switzerland| Australia| Malaysia| Iran
A3: Fernández-Verdejo R. | B3: Fibro-adipogenic progenitors in physiological adipogenesis and intermuscular adipose tissue remodeling | C3: Flores-Opazo, M.| Kopinke, D.| Helmbacher, F.| Fernández-Verdejo, R.| Tuñón-Suárez, M.| Lynch, G.S.| Contreras, O. | D3: 2024 | E3: 45444 | F3: Molecular Aspects of Medicine | G3: 97 | H3: - | I3: - | J3: ISSN-00982997 | K3: Elsevier Ltd | L3: English | M3: 18.2 | N3: 1.0 | O3: 2947 | P3: 10.1016/j.mam.2024.101277 | Q3: Review | R3: 2-s2.0-85193826870 | S3: Louisiana State University| Universidad de O'Higgins| University of Florida| LSU Pennington Biomedical Research Center| Aix-Marseille Université| CNRS| University of Melbourne| Universidad Finis Terrae| University of New South Wales| Victor Chang Cardiac Research Institute | T3: 60157974| 60013959| 60007567| 60034123| 60102127| 60008134| 60021235| 60007566| 60105368| 60343000| 60343038| 60026553| 60028061| 60028333 | U3: Universidad de O’Higgins| University of Florida| University of Florida College of Medicine| Institut de Biologie du Développement de Marseille| Aix Marseille Université| CNRS Centre National de la Recherche Scientifique| Pennington Biomedical Research Center| Louisiana State University| Universidad Finis Terrae| Department of Anatomy and Physiology| Centre for Muscle Research| University of Melbourne| Victor Chang Cardiac Research Institute| UNSW Sydney | V3: Chile| United States| Australia| France
A4: Tuñón-Suárez M. | B4: Fibro-adipogenic progenitors in physiological adipogenesis and intermuscular adipose tissue remodeling | C4: Flores-Opazo, M.| Kopinke, D.| Helmbacher, F.| Fernández-Verdejo, R.| Tuñón-Suárez, M.| Lynch, G.S.| Contreras, O. | D4: 2024 | E4: 45444 | F4: Molecular Aspects of Medicine | G4: 97 | H4: - | I4: - | J4: ISSN-00982997 | K4: Elsevier Ltd | L4: English | M4: 18.2 | N4: 1.0 | O4: 2947 | P4: 10.1016/j.mam.2024.101277 | Q4: Review | R4: 2-s2.0-85193826870 | S4: Louisiana State University| Universidad de O'Higgins| University of Florida| LSU Pennington Biomedical Research Center| Aix-Marseille Université| CNRS| University of Melbourne| Universidad Finis Terrae| University of New South Wales| Victor Chang Cardiac Research Institute | T4: 60157974| 60013959| 60007567| 60034123| 60102127| 60008134| 60021235| 60007566| 60105368| 60343000| 60343038| 60026553| 60028061| 60028333 | U4: Universidad de O’Higgins| University of Florida| University of Florida College of Medicine| Institut de Biologie du Développement de Marseille| Aix Marseille Université| CNRS Centre National de la Recherche Scientifique| Pennington Biomedical Research Center| Louisiana State University| Universidad Finis Terrae| Department of Anatomy and Physiology| Centre for Muscle Research| University of Melbourne| Victor Chang Cardiac Research Institute| UNSW Sydney | V4: Chile| United States| Australia| France
A5: Chavez-Reyes A. | B5: Therapeutic Antisense Oligonucleotides in Oncology: From Bench to Bedside | C5: Çakan, E.| Lara, O.D.| Szymanowska, A.| Bayraktar, E.| Chavez-Reyes, A.| Lopez-Berestein, G.| Amero, P.| Rodriguez-Aguayo, C. | D5: 2024 | E5: 45536 | F5: Cancers | G5: 16 | H5: 17 | I5: - | J5: ISSN-20726694 | K5: Multidisciplinary Digital Publishing Institute (MDPI) | L5: English | M5: 8.8 | N5: 17.0 | O5: 1462 | P5: 10.3390/cancers16172940 | Q5: Review | R5: 2-s2.0-85203665259 | S5: University of Texas MD Anderson Cancer Center| Hacettepe University| University of North Carolina at Chapel Hill| Gaziantep University| Universidad Finis Terrae | T5: 60015023| 60020484| 60025111| 60017595| 60105368 | U5: The University of Texas MD Anderson Cancer Center| Hacettepe Üniversitesi| The University of North Carolina at Chapel Hill| Gaziantep Üniversitesi| Universidad Finis Terrae | V5: Chile| United States| Turkey
A6: Mayo B. | B6: Curcumin Administration Routes in Breast Cancer Treatment | C6: Mayo, B.| Penroz, S.| Torres, K.| Simón, L. | D6: 2024 | E6: 45597 | F6: International Journal of Molecular Sciences | G6: 25 | H6: 21 | I6: - | J6: ISSN-16616596 | K6: Multidisciplinary Digital Publishing Institute (MDPI) | L6: English | M6: 9.0 | N6: 10.0 | O6: 1273 | P6: 10.3390/ijms252111492 | Q6: Review | R6: 2-s2.0-85208575143 | S6: Universidad Finis Terrae | T6: 601053680000000 | U6: Universidad Finis Terrae | V6: Chile
A7: Penroz S. | B7: Curcumin Administration Routes in Breast Cancer Treatment | C7: Mayo, B.| Penroz, S.| Torres, K.| Simón, L. | D7: 2024 | E7: 45597 | F7: International Journal of Molecular Sciences | G7: 25 | H7: 21 | I7: - | J7: ISSN-16616596 | K7: Multidisciplinary Digital Publishing Institute (MDPI) | L7: English | M7: 9.0 | N7: 10.0 | O7: 1273 | P7: 10.3390/ijms252111492 | Q7: Review | R7: 2-s2.0-85208575143 | S7: Universidad Finis Terrae | T7: 601053680000000 | U7: Universidad Finis Terrae | V7: Chile
A8: Torres K. | B8: Curcumin Administration Routes in Breast Cancer Treatment | C8: Mayo, B.| Penroz, S.| Torres, K.| Simón, L. | D8: 2024 | E8: 45597 | F8: International Journal of Molecular Sciences | G8: 25 | H8: 21 | I8: - | J8: ISSN-16616596 | K8: Multidisciplinary Digital Publishing Institute (MDPI) | L8: English | M8: 9.0 | N8: 10.0 | O8: 1273 | P8: 10.3390/ijms252111492 | Q8: Review | R8: 2-s2.0-85208575143 | S8: Universidad Finis Terrae | T8: 601053680000000 | U8: Universidad Finis Terrae | V8: Chile
A9: Simón L. | B9: Curcumin Administration Routes in Breast Cancer Treatment | C9: Mayo, B.| Penroz, S.| Torres, K.| Simón, L. | D9: 2024 | E9: 45597 | F9: International Journal of Molecular Sciences | G9: 25 | H9: 21 | I9: - | J9: ISSN-16616596 | K9: Multidisciplinary Digital Publishing Institute (MDPI) | L9: English | M9: 9.0 | N9: 10.0 | O9: 1273 | P9: 10.3390/ijms252111492 | Q9: Review | R9: 2-s2.0-85208575143 | S9: Universidad Finis Terrae | T9: 601053680000000 | U9: Universidad Finis Terrae | V9: Chile
A10: Fuentealba J.M. | B10: Management of alcohol use disorder: a gastroenterology and hepatology-focused perspective | C10: Díaz, L.A.| König, D.| Weber, S.| Ayares, G.| Fuentealba, J.M.| Vázquez, V.| Bataller, R.| Kamath, P.S.| Winder, G.S.| Leggio, L.| Arab, J.P. | D10: 2025 | E10: 45778 | F10: The Lancet Gastroenterology and Hepatology | G10: 10 | H10: 5 | I10: 475-490 | J10: ISSN-24681253 | K10: Elsevier Ltd | L10: English | M10: 64.3 | N10: 1.0 | O10: 13113 | P10: 10.1016/S2468-1253(24)00380-7 | Q10: Review | R10: 2-s2.0-86000364846 | S10: National Institutes of Health| Medical University of Vienna| Mayo Clinic Rochester, MN| Centro de Investigación Biomédica en Red| Virginia Commonwealth University| Universidad Finis Terrae| University of Michigan, Ann Arbor| University of California at San Diego| Instituto de Salud Carlos III| Pontificia Universidad Católica de Chile| August Pi i Sunyer Biomedical Research Institute| Instituto Tecnologico de Estudios Superiores de Monterrey | T10: 60029681| 60088718| 60030612| 60011394| 60105368| 60007966| 60001285| 60078879| 60010814| 60030315| 60005558| 60025778| 60033182| 60006577| 60020468| 60016730| 60010966 | U10: Pontificia Universidad Católica de Chile| Escuela de Medicina| University of California, San Diego| Medizinische Universität Wien| Universidad Finis Terrae| Tecnológico de Monterrey| Escuela de Medicina y Ciencias de la Salud TecSalud| Centro de Investigación Biomédica en Red de Enfermedades Hepáticas y Digestivas| Institut d'Investigacions Biomèdiques August Pi i Sunyer - IDIBAPS| Hospital Clínic de Barcelona| Mayo Clinic| University of Michigan, Ann Arbor| University of Michigan Medical School| National Institutes of Health (NIH)| National Institute on Drug Abuse (NIDA)| National Institute on Alcohol Abuse and Alcoholism (NIAAA)| VCU School of Medicine | V10: Chile| Austria| Mexico| Spain| United States
A11: Hidalgo-Rosa Y. | B11: UiO-66(Zr) as drug delivery system for non-steroidal anti-inflammatory drugs | C11: Salazar, J.| Hidalgo-Rosa, Y.| Burboa, P.C.| Wu, Y.-N.| Escalona, N.| Leiva, A.| Zarate, X.| Schott, E. | D11: 2024 | E11: 45444 | F11: Journal of Controlled Release | G11: 370 | H11: - | I11: 392-404 | J11: ISSN-01683659 | K11: Elsevier B.V. | L11: English | M11: 19.4 | N11: 2.0 | O11: 2.47 | P11: 10.1016/j.jconrel.2024.04.035 | Q11: Article | R11: 2-s2.0-85192014123 | S11: Universidad Autónoma de Chile| Ministerio de Planificación, Chile| Universidad Finis Terrae| Rutgers - The State University of New Jersey, New Brunswick| Pontificia Universidad Católica de Chile| Tongji University | T11: 60029681| 60005208| 60073652| 60105371| 60281487| 60105368 | U11: Pontificia Universidad Católica de Chile| Rutgers New Jersey Medical School| Tongji University| Universidad Autónoma de Chile| Núcleo Milenio en Procesos Catalíticos hacia la Química Sustentable| Universidad Finis Terrae | V11: Chile| China| United States
A12: Strauss F.J. | B12: Impact of keratinized mucosa on implant-health related parameters: A 10-year prospective re-analysis study | C12: Mancini, L.| Strauss, F.J.| Lim, H.-C.| Tavelli, L.| Jung, R.E.| Naenni, N.| Thoma, D.S. | D12: 2024 | E12: 45444 | F12: Clinical Implant Dentistry and Related Research | G12: 26 | H12: 3 | I12: 554-563 | J12: ISSN-15230899 | K12: John Wiley and Sons Inc | L12: English | M12: 6.4 | N12: 7.0 | O12: 1315 | P12: 10.1111/cid.13314 | Q12: Article | R12: 2-s2.0-85186625457 | S12: Kyung Hee University| University of L'Aquila| Harvard University| University of Zurich| Universidad Finis Terrae| Yonsei University| Universidad de Chile | T12: 60012614| 60018783| 127992824| 60105368| 60012464| 60001873| 60005856| 60115878 | U12: Universität Zürich| Università degli Studi dell'Aquila| Center for Clinical Research and Evidence Synthesis in Oral Tissue Regeneration (CRITERION)| Universidad Finis Terrae| Universidad de Chile| Kyung Hee University| Harvard School of Dental Medicine| Yonsei University College of Dentistry | V12: Chile| South Korea| United States| Switzerland| Italy
A13: Yanine F.F. | B13: A comprehensive review of smart energy management systems for photovoltaic power generation utilizing the internet of things | C13: Rao, C.K.| Sahoo, S.K.| Yanine, F.F. | D13: 2025 | E13: 45839 | F13: Unconventional Resources | G13: 7 | H13: - | I13: - | J13: ISSN-26665190 | K13: KeAi Communications Co. | L13: English | M13: 6.4 | N13: 25.0 | O13: 0.864 | P13: 10.1016/j.uncres.2025.100197 | Q13: Review | R13: 2-s2.0-105004998221 | S13: Biju Patnaik University of Technology| Universidad Finis Terrae| Aditya Institute of Technology and Management | T13: 60077979| 60114758| 60114662| 60105368 | U13: Biju Patnaik University of Technology| BPUT, Parala Maharaja Engineering College| Aditya Institute of Technology and Management| Universidad Finis Terrae | V13: Chile| India
A14: Yanine F.F. | B14: IoT enabled Intelligent Energy Management System employing advanced forecasting algorithms and load optimization strategies to enhance renewable energy generation | C14: Krishna Rao, C.| Sahoo, S.K.| Yanine, F.F. | D14: 2024 | E14: 45292 | F14: Unconventional Resources | G14: 4 | H14: - | I14: - | J14: ISSN-26665190 | K14: KeAi Communications Co. | L14: English | M14: 5.3 | N14: 29.0 | O14: 0.828 | P14: 10.1016/j.uncres.2024.100101 | Q14: Article | R14: 2-s2.0-85200812969 | S14: Biju Patnaik University of Technology| Universidad Finis Terrae| Aditya Institute of Technology and Management | T14: 60114758| 60077979| 60114662| 60105368 | U14: BPUT, Parala Maharaja Engineering College| Biju Patnaik University of Technology| Aditya Institute of Technology and Management| Universidad Finis Terrae | V14: Chile| India
A15: Fernández-Verdejo R. | B15: Energy Expenditure in Humans: Principles, Methods, and Changes Throughout the Life Course | C15: Fernández-Verdejo, R.| Sanchez-Delgado, G.| Ravussin, E. | D15: 2024 | E15: 45533 | F15: Annual Review of Nutrition | G15: 44 | H15: 1 | I15: 51-76 | J15: ISSN-01999885 | K15: Annual Reviews Inc. | L15: English | M15: 22.3 | N15: 1.0 | O15: 4435 | P15: 10.1146/annurev-nutr-062122-031443 | Q15: Review | R15: 2-s2.0-85202905959 | S15: Louisiana State University| LSU Pennington Biomedical Research Center| Centro de Investigación Biomédica en Red| Université de Sherbrooke| Universidad Finis Terrae| Instituto de Salud Carlos III| University of Granada | T15: 60021235| 60007566| 60105368| 60027844| 60001602| 60104562| 60104563| 60011832| 60004772| 114245405 | U15: Pennington Biomedical Research Center| Louisiana State University| Universidad Finis Terrae| Universidad de Granada| Instituto de Salud Carlos III| Centro de Investigación Biomédica en Red| Centro de Investigación Biomédica en Red-Fisiopatología de la Obesidad y Nutrición| Université de Sherbrooke| Centre Hospitalier Universitaire de Sherbrooke| Instituto de Investigación Biosanitaria ibs.GRANADA | V15: Chile| Spain| United States| Canada
A16: Henríquez-Olguín C. | B16: Reducing the mitochondrial oxidative burden alleviates lipid-induced muscle insulin resistance in humans | C16: Fiorenza, M.| Onslev, J.| Henríquez-Olguín, C.| Persson, K.W.| Hesselager, S.A.| Jensen, T.E.| Wojtaszewski, J.F.P.| Hostrup, M.| Bangsbo, J. | D16: 2024 | E16: 45597 | F16: System.Xml.XmlElement | G16: 10 | H16: 44 | I16: - | J16: ISSN-23752548 | K16: American Association for the Advancement of Science | L16: English | M16: 19.6 | N16: 4.0 | O16: 4324 | P16: 10.1126/sciadv.adq4461 | Q16: Article | R16: 2-s2.0-85208163795 | S16: University of Copenhagen| Universidad Finis Terrae | T16: 60030840| 60105368 | U16: Københavns Universitet| Universidad Finis Terrae | V16: Chile| Denmark
A17: Salas-Guzmán N. | B17: STEM and gender gap: a systematic review in WoS, Scopus, and ERIC databases (2012–2022) | C17: Beroíza-Valenzuela, F.| Salas-Guzmán, N. | D17: 2024 | E17: 45292 | F17: Frontiers in Education | G17: 9 | H17: - | I17: - | J17: ISSN-2504284X | K17: Frontiers Media SA | L17: English | M17: 3.7 | N17: 29.0 | O17: 0.65 | P17: 10.3389/feduc.2024.1378640 | Q17: Review | R17: 2-s2.0-85193689500 | S17: Universidad Finis Terrae| Universidad de Chile| Universidad Metropolitana de Ciencias de la Educación | T17: 60003126| 60012464| 60105368 | U17: Universidad Metropolitana de Ciencias de la Educación| Universidad de Chile| Universidad Finis Terrae | V17: Chile
A18: Yanine F.F. | B18: An IoT-based intelligent smart energy monitoring system for solar PV power generation | C18: Rao, C.K.| Sahoo, S.K.| Yanine, F.F. | D18: 2024 | E18: 45292 | F18: Energy Harvesting and Systems | G18: 11 | H18: 1 | I18: - | J18: ISSN-23298774 | K18: Walter de Gruyter GmbH | L18: English | M18: 3.8 | N18: 40.0 | O18: 0.358 | P18: 10.1515/ehs-2023-0015 | Q18: Article | R18: 2-s2.0-85175966754 | S18: Biju Patnaik University of Technology| Universidad Finis Terrae| Aditya Institute of Technology and Management | T18: 60114758| 60077979| 60114662| 60105368 | U18: BPUT, Parala Maharaja Engineering College| Biju Patnaik University of Technology| Aditya Institute of Technology and Management| Universidad Finis Terrae | V18: Chile| India
A19: Morales J.-P. | B19: Interoceptive awareness in a clinical setting: the need to bring interoceptive perspectives into clinical evaluation | C19: Solano Durán, P.| Morales, J.-P.| Huepe, D. | D19: 2024 | E19: 45292 | F19: Frontiers in Psychology | G19: 15 | H19: - | I19: - | J19: ISSN-16641078 | K19: Frontiers Media SA | L19: English | M19: 6.3 | N19: 17.0 | O19: 0.872 | P19: 10.3389/fpsyg.2024.1244701 | Q19: Short Survey | R19: 2-s2.0-85196854825 | S19: The University of Sydney| Costa Rica Institute of Technology| Universidad Adolfo Ibáñez| Universidad Finis Terrae | T19: 60003942| 60099123| 60105368| 60212023 | U19: Universidad Adolfo Ibáñez| Instituto Tecnológico de Costa Rica| Universidad Finis Terrae| The University of Sydney Business School | V19: Chile| Costa Rica| Australia
A20: De la Fuente M. | B20: Liver X receptor unlinks intestinal regeneration and tumorigenesis | C20: Das, S.| Parigi, S.M.| Luo, X.| Fransson, J.| Kern, B.C.| Okhovat, A.| Diaz, O.E.| Sorini, C.| Czarnewski, P.| Webb, A.T.| Morales, R.A.| Lebon, S.| Monasterio, G.| Castillo, F.| Tripathi, K.P.| He, N.| Pelczar, P.| Schaltenberg, N.| De la Fuente, M.| López-Köstner, F.| Nylén, S.| Larsen, H.L.| Kuiper, R.| Antonson, P.| Hermoso, M.A.| Huber, S.| Biton, M.| Scharaw, S.| Gustafsson, J.-Å.| Katajisto, P.| Villablanca, E.J. | D20: 2025 | E20: 45687 | F20: Nature | G20: 637 | H20: 8048 | I20: 1198-1206 | J20: ISSN-00280836 | K20: Nature Research | L20: English | M20: 77.7 | N20: 1.0 | O20: 19713 | P20: 10.1038/s41586-024-08247-6 | Q20: Article | R20: 2-s2.0-85209738764 | S20: Uppsala University| Karolinska Institutet| Novo Nordisk Foundation| Max Planck Institute of Molecular Cell Biology and Genetics| Universidad Finis Terrae| KTH Royal Institute of Technology| University of Helsinki| University of Houston| Clínica Las Condes| National Veterinary Institute Norway| Weizmann Institute of Science| Stockholm University| University of Copenhagen| University of Hamburg| Rockefeller University| Universidad de los Andes Mérida| Universidad de Chile | T20: 60012311| 100803701| 60028378| 60237270| 60017563| 60005036| 60017912| 60105368| 60002946| 60012464| 60002439| 60030840| 60006179| 60022237| 60151391| 60005837| 60002952| 60022076| 60019295| 60026827| 60000456 | U20: Karolinska Institutet| Center of Molecular Medicine| Stockholms universitet| Science for Life Laboratory| Weizmann Institute of Science Israel| Universitätsklinikum Hamburg-Eppendorf| Clínica Las Condes| Universidad Finis Terrae| Facultad de Medicina de la Universidad de Chile| Universidad de Chile| Universidad De Los Andes, Merida| Københavns Universitet| Novo Nordisk A/S| Veterinærinstituttet| College of Natural Sciences and Mathematics| University of Houston| Helsingin Yliopisto| Institute of Biotechnology| Karolinska Universitetssjukhuset| Rockefeller University| Max Planck Institute of Molecular Cell Biology and Genetics | V20: Chile| Norway| Israel| Finland| United States| Germany| Denmark| Venezuela| Sweden
A21: Benites M.H. | B21: Ventilation-induced acute kidney injury in acute respiratory failure: Do PEEP levels matter? | C21: Benites, M.H.| Suarez-Sipmann, F.| Kattan, E.| Cruces, P.| Retamal, J. | D21: 2025 | E21: 45992 | F21: Critical Care | G21: 29 | H21: 1 | I21: - | J21: ISSN-13648535 | K21: BioMed Central Ltd | L21: English | M21: 16.0 | N21: 3.0 | O21: 3002 | P21: 10.1186/s13054-025-05343-5 | Q21: Review | R21: 2-s2.0-105000547419 | S21: Uppsala University| Hospital Universitario de la Princesa| Universidad Andrés Bello| Centro de Investigación Biomédica en Red| Universidad Finis Terrae| Clínica Las Condes| Instituto de Salud Carlos III| Pontificia Universidad Católica de Chile | T21: 60017912| 60105368| 60088718| 60029681| 60102756| 60001602| 60024257| 60003858| 60002636| 60281764| 60281394 | U21: Clínica Las Condes| Universidad Finis Terrae| Escuela de Medicina| Pontificia Universidad Católica de Chile| Centro de Investigación Biomédica en Red de Enfermedades Respiratorias| Instituto de Salud Carlos III| Hospital Universitario de la Princesa| Uppsala Universitet| Universidad Andrés Bello| Facultad de Ciencias de la Vida| Hospital El Carmen Dr. Luis Valentín Ferrada | V21: Chile| Spain| Sweden
